<mujoco model="dogurdf">
  <compiler angle="radian"/>

  <asset>
    <mesh name="base" content_type="model/stl" file="base.STL"/>
    <mesh name="hip" content_type="model/stl" file="hip.STL"/>
    <mesh name="front_gear" content_type="model/stl" file="front_gear.STL"/>
    <mesh name="back_gear" content_type="model/stl" file="back_gear.STL"/>
  </asset>

  <worldbody>
    <geom type="mesh" rgba="1 1 1 1" mesh="base"/>
    <body name="hip" pos="0.11264 0.0419623 0.017594" quat="0.77464 0.632403 0 0">
      <inertial pos="-0.106808 -0.00999326 -0.0021685" quat="0.45366 0.532649 0.532131 0.476774" mass="1.02487" diaginertia="0.00335222 0.00273958 0.000981401"/>
      <joint name="6" pos="0 0 0" axis="0 1 0"/>
      <geom type="mesh" rgba="0.792157 0.819608 0.933333 1" mesh="hip"/>
      <geom pos="-0.066 -0.00585 0" quat="0.622192 -0.622194 -0.335969 -0.33597" type="mesh" rgba="0.792157 0.819608 0.933333 1" mesh="back_gear"/>
      <body name="front_gear" pos="-0.166 0.012614 0" quat="0.619643 0.340648 -0.340649 -0.619645">
        <inertial pos="0.00551781 0 0" mass="0.0385237" diaginertia="1.02723e-05 9.4739e-06 9.4739e-06"/>
        <joint name="font_gear" pos="0 0 0" axis="1 0 0"/>
        <geom type="mesh" rgba="0.776471 0.756863 0.737255 1" mesh="front_gear"/>
      </body>
    </body>
  </worldbody>
  <actuator>
    <motor name="motor_font_gear" joint="font_gear" gear="100"/>
    <motor name="motor_font" joint="6" gear="100"/>
  </actuator>
</mujoco>
