<?xml version="1.0" encoding="utf-8"?>
<!-- This URDF was automatically created by SolidWorks to URDF Exporter! Originally created by Stephen Brawner (brawner@gmail.com) 
     Commit Version: 1.6.0-4-g7f85cfe  Build Version: 1.6.7995.38578
     For more information, please see http://wiki.ros.org/sw_urdf_exporter -->
<robot
  name="mos_dog0727">
  <link
    name="hip_motor">
    <inertial>
      <origin
        xyz="0.0194551268079176 6.36966361748578E-05 -9.61004841047268E-05"
        rpy="0 0 0" />
      <mass
        value="0.193691939886921" />
      <inertia
        ixx="0.000212643438348687"
        ixy="2.52844683099132E-08"
        ixz="-3.06361088010136E-08"
        iyy="0.000111361588040042"
        iyz="-3.62933591243464E-07"
        izz="0.000115174943226426" />
    </inertial>
    <visual>
      <origin
        xyz="0 0 0"
        rpy="0 0 0" />
      <geometry>
        <mesh
          filename="../meshes/hip_motor.STL" />
      </geometry>
      <material
        name="">
        <color
          rgba="1 1 1 1" />
      </material>
    </visual>
    <collision>
      <origin
        xyz="0 0 0"
        rpy="0 0 0" />
      <geometry>
        <mesh
          filename="../meshes/hip_motor.STL" />
      </geometry>
    </collision>
  </link>
  <link
    name="hip_body">
    <inertial>
      <origin
        xyz="0.112158833215 -0.010467888429627 0.000152165519640979"
        rpy="0 0 0" />
      <mass
        value="0.97840250966566" />
      <inertia
        ixx="0.000911112321686209"
        ixy="5.94741312881277E-08"
        ixz="-1.41077325491889E-07"
        iyy="0.00263457972761172"
        iyz="-3.8832300327873E-07"
        izz="0.00207388396760231" />
    </inertial>
    <visual>
      <origin
        xyz="0 0 0"
        rpy="0 0 0" />
      <geometry>
        <mesh
          filename="../meshes/hip_body.STL" />
      </geometry>
      <material
        name="">
        <color
          rgba="0.792156862745098 0.819607843137255 0.933333333333333 1" />
      </material>
    </visual>
    <collision>
      <origin
        xyz="0 0 0"
        rpy="0 0 0" />
      <geometry>
        <mesh
          filename="../meshes/hip_body.STL" />
      </geometry>
    </collision>
  </link>
  <joint
    name="hip_joint"
    type="revolute">
    <origin
      xyz="-0.232 0 0"
      rpy="-0.40508 0 0" />
    <parent
      link="hip_motor" />
    <child
      link="hip_body" />
    <axis
      xyz="1 0 0" />
    <limit
      lower="0"
      upper="0"
      effort="0"
      velocity="0" />
  </joint>
  <link
    name="front_gear">
    <inertial>
      <origin
        xyz="-0.00709611298298662 -4.30211422042248E-16 -1.00613961606655E-15"
        rpy="0 0 0" />
      <mass
        value="0.0385237466196057" />
      <inertia
        ixx="1.02723402754827E-05"
        ixy="-2.11758236813575E-21"
        ixz="-2.11758236813575E-22"
        iyy="9.4738981050848E-06"
        iyz="-2.5410988417629E-21"
        izz="9.4738981050848E-06" />
    </inertial>
    <visual>
      <origin
        xyz="0 0 0"
        rpy="0 0 0" />
      <geometry>
        <mesh
          filename="../meshes/front_gear.STL" />
      </geometry>
      <material
        name="">
        <color
          rgba="0.776470588235294 0.756862745098039 0.737254901960784 1" />
      </material>
    </visual>
    <collision>
      <origin
        xyz="0 0 0"
        rpy="0 0 0" />
      <geometry>
        <mesh
          filename="../meshes/front_gear.STL" />
      </geometry>
    </collision>
  </link>
  <joint
    name="font_gear"
    type="continuous">
    <origin
      xyz="0.166 0 0"
      rpy="-2.1362 0 -1.5708" />
    <parent
      link="hip_body" />
    <child
      link="front_gear" />
    <axis
      xyz="1 0 0" />
    <limit
      lower="-1.57"
      upper="1.57"
      effort="20"
      velocity="2" />
  </joint>
  <link
    name="front_middle">
    <inertial>
      <origin
        xyz="0.0719699196521946 -0.00459233449849147 -0.0434001666746889"
        rpy="0 0 0" />
      <mass
        value="0.171586598360634" />
      <inertia
        ixx="0.000443406919636758"
        ixy="7.55932600983705E-07"
        ixz="7.09320700607168E-06"
        iyy="0.000439776385998155"
        iyz="-4.21570917357198E-05"
        izz="5.32958965335921E-05" />
    </inertial>
    <visual>
      <origin
        xyz="0 0 0"
        rpy="0 0 0" />
      <geometry>
        <mesh
          filename="../meshes/front_middle.STL" />
      </geometry>
      <material
        name="">
        <color
          rgba="0.776470588235294 0.756862745098039 0.737254901960784 1" />
      </material>
    </visual>
    <collision>
      <origin
        xyz="0 0 0"
        rpy="0 0 0" />
      <geometry>
        <mesh
          filename="../meshes/front_middle.STL" />
      </geometry>
    </collision>
  </link>
  <joint
    name="front_middle"
    type="continuous">
    <origin
      xyz="0 0.035318 -0.036806"
      rpy="0.56657 0 -3.1416" />
    <parent
      link="front_gear" />
    <child
      link="front_middle" />
    <axis
      xyz="1 0 0" />
    <limit
      lower="0"
      upper="0"
      effort="0"
      velocity="0" />
  </joint>
  <link
    name="shank_link">
    <inertial>
      <origin
        xyz="0.0722262549948705 0.00462277734098443 0.0143911382744808"
        rpy="0 0 0" />
      <mass
        value="0.046939056546293" />
      <inertia
        ixx="4.10947592671335E-06"
        ixy="5.12624832799925E-06"
        ixz="5.94860889375511E-07"
        iyy="0.000133019442393395"
        iyz="3.83014809794483E-08"
        izz="0.000135918543416535" />
    </inertial>
    <visual>
      <origin
        xyz="0 0 0"
        rpy="0 0 0" />
      <geometry>
        <mesh
          filename="../meshes/shank_link.STL" />
      </geometry>
      <material
        name="">
        <color
          rgba="1 1 1 1" />
      </material>
    </visual>
    <collision>
      <origin
        xyz="0 0 0"
        rpy="0 0 0" />
      <geometry>
        <mesh
          filename="../meshes/shank_link.STL" />
      </geometry>
    </collision>
  </link>
  <joint
    name="shank_joint"
    type="continuous">
    <origin
      xyz="0.053931 -0.016692 -0.15549"
      rpy="-1.5708 0.018564 -1.5708" />
    <parent
      link="front_middle" />
    <child
      link="shank_link" />
    <axis
      xyz="0 0 1" />
  </joint>
  <link
    name="back_gear">
    <inertial>
      <origin
        xyz="-1.38777878078145E-15 -1.52655665885959E-16 0.0213772870634909"
        rpy="0 0 0" />
      <mass
        value="0.046468593190171" />
      <inertia
        ixx="1.044546863586E-05"
        ixy="8.470329472543E-22"
        ixz="1.79994501291539E-21"
        iyy="1.044546863586E-05"
        iyz="-5.0821976835258E-21"
        izz="1.19792859161395E-05" />
    </inertial>
    <visual>
      <origin
        xyz="0 0 0"
        rpy="0 0 0" />
      <geometry>
        <mesh
          filename="../meshes/back_gear.STL" />
      </geometry>
      <material
        name="">
        <color
          rgba="0.792156862745098 0.819607843137255 0.933333333333333 1" />
      </material>
    </visual>
    <collision>
      <origin
        xyz="0 0 0"
        rpy="0 0 0" />
      <geometry>
        <mesh
          filename="../meshes/back_gear.STL" />
      </geometry>
    </collision>
  </link>
  <joint
    name="back_gear"
    type="fixed">
    <origin
      xyz="0.066 -0.00585 0"
      rpy="1.5708 0.99023 3.1416" />
    <parent
      link="hip_body" />
    <child
      link="back_gear" />
    <axis
      xyz="0 0 0" />
  </joint>
  <link
    name="back_middle">
    <inertial>
      <origin
        xyz="-0.0295367878866366 -0.0475320764348792 -8.25635702465105E-06"
        rpy="0 0 0" />
      <mass
        value="0.218415805551476" />
      <inertia
        ixx="0.000728917714027351"
        ixy="-1.45431101195225E-05"
        ixz="-2.52904361687544E-09"
        iyy="8.77564112554255E-05"
        iyz="-1.00893607165187E-07"
        izz="0.000666819472527857" />
    </inertial>
    <visual>
      <origin
        xyz="0 0 0"
        rpy="0 0 0" />
      <geometry>
        <mesh
          filename="../meshes/back_middle.STL" />
      </geometry>
      <material
        name="">
        <color
          rgba="0.776470588235294 0.756862745098039 0.737254901960784 1" />
      </material>
    </visual>
    <collision>
      <origin
        xyz="0 0 0"
        rpy="0 0 0" />
      <geometry>
        <mesh
          filename="../meshes/back_middle.STL" />
      </geometry>
    </collision>
  </link>
  <joint
    name="back_middle"
    type="fixed">
    <origin
      xyz="-0.01898 -0.047347 0.038"
      rpy="2.2819 1.5708 0" />
    <parent
      link="back_gear" />
    <child
      link="back_middle" />
    <axis
      xyz="0 0 0" />
  </joint>
  <link
    name="thigh">
    <inertial>
      <origin
        xyz="-0.0675793464112738 0.00375946274148686 0.0394745065429045"
        rpy="0 0 0" />
      <mass
        value="0.28622252788818" />
      <inertia
        ixx="7.0874841436314E-05"
        ixy="-8.83745676017581E-05"
        ixz="1.21994032732064E-06"
        iyy="0.00125411480709582"
        iyz="3.66046030698773E-08"
        izz="0.00130942111467501" />
    </inertial>
    <visual>
      <origin
        xyz="0 0 0"
        rpy="0 0 0" />
      <geometry>
        <mesh
          filename="../meshes/thigh.STL" />
      </geometry>
      <material
        name="">
        <color
          rgba="0.792156862745098 0.819607843137255 0.933333333333333 1" />
      </material>
    </visual>
    <collision>
      <origin
        xyz="0 0 0"
        rpy="0 0 0" />
      <geometry>
        <mesh
          filename="../meshes/thigh.STL" />
      </geometry>
    </collision>
  </link>
  <joint
    name="thigh"
    type="continuous">
    <origin
      xyz="0 -0.18 -3.1403E-05"
      rpy="1.5708 -1.1311 -1.5708" />
    <parent
      link="back_middle" />
    <child
      link="thigh" />
    <axis
      xyz="0 0 1" />
  </joint>
</robot>